<?xml version="1.0" encoding="UTF-8"?>
<!-- Generated by org.testng.reporters.JUnitReportReporter -->
<testsuite skipped="0" hostname="Inboundsys-Mac-Dhanalakshmi.local" name="com.hubspotcrm.Testcases.HomePageTest" tests="5" failures="3" timestamp="29 Oct 2018 12:02:42 GMT" time="75.049" errors="0">
  <testcase name="verifyloggedusername" time="12.983" classname="com.hubspotcrm.Testcases.HomePageTest"/>
  <testcase name="verifylogourlTest" time="16.039" classname="com.hubspotcrm.Testcases.HomePageTest">
    <failure type="java.lang.AssertionError" message="expected [https://app.hubspot.com/reports-dashboard/5068902/sales] but found [https://app.hubspot.com/reports-dashboard/5068902/view]">
      <![CDATA[java.lang.AssertionError: expected [https://app.hubspot.com/reports-dashboard/5068902/sales] but found [https://app.hubspot.com/reports-dashboard/5068902/view]
at org.testng.Assert.fail(Assert.java:96)
at org.testng.Assert.failNotEquals(Assert.java:776)
at org.testng.Assert.assertEqualsImpl(Assert.java:137)
at org.testng.Assert.assertEquals(Assert.java:118)
at org.testng.Assert.assertEquals(Assert.java:453)
at org.testng.Assert.assertEquals(Assert.java:463)
at com.hubspotcrm.Testcases.HomePageTest.verifylogourlTest(HomePageTest.java:44)
at sun.reflect.NativeMethodAccessorImpl.invoke0(Native Method)
at sun.reflect.NativeMethodAccessorImpl.invoke(NativeMethodAccessorImpl.java:62)
at sun.reflect.DelegatingMethodAccessorImpl.invoke(DelegatingMethodAccessorImpl.java:43)
at java.lang.reflect.Method.invoke(Method.java:498)
at org.testng.internal.MethodInvocationHelper.invokeMethod(MethodInvocationHelper.java:124)
at org.testng.internal.Invoker.invokeMethod(Invoker.java:583)
at org.testng.internal.Invoker.invokeTestMethod(Invoker.java:719)
at org.testng.internal.Invoker.invokeTestMethods(Invoker.java:989)
at org.testng.internal.TestMethodWorker.invokeTestMethods(TestMethodWorker.java:125)
at org.testng.internal.TestMethodWorker.run(TestMethodWorker.java:109)
at java.util.concurrent.ThreadPoolExecutor.runWorker(ThreadPoolExecutor.java:1142)
at java.util.concurrent.ThreadPoolExecutor$Worker.run(ThreadPoolExecutor.java:617)
at java.lang.Thread.run(Thread.java:745)
]]>
    </failure>
  </testcase> <!-- verifylogourlTest -->
  <testcase name="verifycontacturlTest" time="14.196" classname="com.hubspotcrm.Testcases.HomePageTest">
    <failure type="java.lang.AssertionError" message="expected [https://app.hubspot.com/contacts/5068902/contacts/list/view/all/?] but found [https://app.hubspot.com/contacts/5068902/contacts]">
      <![CDATA[java.lang.AssertionError: expected [https://app.hubspot.com/contacts/5068902/contacts/list/view/all/?] but found [https://app.hubspot.com/contacts/5068902/contacts]
at org.testng.Assert.fail(Assert.java:96)
at org.testng.Assert.failNotEquals(Assert.java:776)
at org.testng.Assert.assertEqualsImpl(Assert.java:137)
at org.testng.Assert.assertEquals(Assert.java:118)
at org.testng.Assert.assertEquals(Assert.java:453)
at org.testng.Assert.assertEquals(Assert.java:463)
at com.hubspotcrm.Testcases.HomePageTest.verifycontacturlTest(HomePageTest.java:49)
at sun.reflect.NativeMethodAccessorImpl.invoke0(Native Method)
at sun.reflect.NativeMethodAccessorImpl.invoke(NativeMethodAccessorImpl.java:62)
at sun.reflect.DelegatingMethodAccessorImpl.invoke(DelegatingMethodAccessorImpl.java:43)
at java.lang.reflect.Method.invoke(Method.java:498)
at org.testng.internal.MethodInvocationHelper.invokeMethod(MethodInvocationHelper.java:124)
at org.testng.internal.Invoker.invokeMethod(Invoker.java:583)
at org.testng.internal.Invoker.invokeTestMethod(Invoker.java:719)
at org.testng.internal.Invoker.invokeTestMethods(Invoker.java:989)
at org.testng.internal.TestMethodWorker.invokeTestMethods(TestMethodWorker.java:125)
at org.testng.internal.TestMethodWorker.run(TestMethodWorker.java:109)
at java.util.concurrent.ThreadPoolExecutor.runWorker(ThreadPoolExecutor.java:1142)
at java.util.concurrent.ThreadPoolExecutor$Worker.run(ThreadPoolExecutor.java:617)
at java.lang.Thread.run(Thread.java:745)
]]>
    </failure>
  </testcase> <!-- verifycontacturlTest -->
  <testcase name="verifycompaniesurlTest" time="18.879" classname="com.hubspotcrm.Testcases.HomePageTest"/>
  <testcase name="verifyactivityurlTest" time="12.952" classname="com.hubspotcrm.Testcases.HomePageTest">
    <failure type="java.lang.AssertionError" message="expected [https://app.hubspot.com/activity-feed/5068902/view] but found [https://app.hubspot.com/activity-feed/5068902]">
      <![CDATA[java.lang.AssertionError: expected [https://app.hubspot.com/activity-feed/5068902/view] but found [https://app.hubspot.com/activity-feed/5068902]
at org.testng.Assert.fail(Assert.java:96)
at org.testng.Assert.failNotEquals(Assert.java:776)
at org.testng.Assert.assertEqualsImpl(Assert.java:137)
at org.testng.Assert.assertEquals(Assert.java:118)
at org.testng.Assert.assertEquals(Assert.java:453)
at org.testng.Assert.assertEquals(Assert.java:463)
at com.hubspotcrm.Testcases.HomePageTest.verifyactivityurlTest(HomePageTest.java:59)
at sun.reflect.NativeMethodAccessorImpl.invoke0(Native Method)
at sun.reflect.NativeMethodAccessorImpl.invoke(NativeMethodAccessorImpl.java:62)
at sun.reflect.DelegatingMethodAccessorImpl.invoke(DelegatingMethodAccessorImpl.java:43)
at java.lang.reflect.Method.invoke(Method.java:498)
at org.testng.internal.MethodInvocationHelper.invokeMethod(MethodInvocationHelper.java:124)
at org.testng.internal.Invoker.invokeMethod(Invoker.java:583)
at org.testng.internal.Invoker.invokeTestMethod(Invoker.java:719)
at org.testng.internal.Invoker.invokeTestMethods(Invoker.java:989)
at org.testng.internal.TestMethodWorker.invokeTestMethods(TestMethodWorker.java:125)
at org.testng.internal.TestMethodWorker.run(TestMethodWorker.java:109)
at java.util.concurrent.ThreadPoolExecutor.runWorker(ThreadPoolExecutor.java:1142)
at java.util.concurrent.ThreadPoolExecutor$Worker.run(ThreadPoolExecutor.java:617)
at java.lang.Thread.run(Thread.java:745)
]]>
    </failure>
  </testcase> <!-- verifyactivityurlTest -->
</testsuite> <!-- com.hubspotcrm.Testcases.HomePageTest -->
